<?xml version='1.0' encoding='UTF-8'?>
<robot name="simple_truck">
  <link name="main">
    <visual><geometry> <mesh filename="meshes/main.glb"/> </geometry></visual>
    <collision>
      <origin xyz="5 0 2" rpy="0 0 0"/>
      <geometry> <box size="21 6.8 3"/> </geometry>
    </collision>
    <collision>
      <origin xyz="2 0 4.5" rpy="0 0 0"/>
      <geometry> <box size="16 7.2 2"/> </geometry>
    </collision>
    <collision>
      <origin xyz="12 0 6.2" rpy="0 0 0"/>
      <geometry> <box size="6 6.8 5.6"/> </geometry>
    </collision>
    <collision>
      <geometry> <cylinder radius="0.45" length="38"/> </geometry>
      <origin xyz="8.2 -1.2 9.45" rpy="0.98 0.02 0.21"/>
    </collision>
    <collision>
      <geometry> <cylinder radius="0.45" length="38"/> </geometry>
      <origin xyz="8.2 0.2 9.45" rpy="0.98 0.02 0.21"/>
    </collision>
    <collision>
      <geometry> <cylinder radius="0.45" length="38"/> </geometry>
      <origin xyz="8.2 1.58 9.45" rpy="0.98 0.02 0.21"/>
    </collision>
  </link>
  <link name="tire1">
    <visual><geometry> <mesh filename="meshes/tire1.glb"/> </geometry></visual>
  </link>
  <link name="tire2">
    <visual><geometry> <mesh filename="meshes/tire2.glb"/> </geometry></visual>
  </link>
  <joint name="tire1" type="revolute">
    <parent link="main"/>
    <child link="tire1"/>
    <origin xyz="11.3 3.0 1.62" rpy="0 0 0"/>
    <axis xyz="0 0 1"/>
    <limit lower="-1.00" upper="1.00" effort="0" velocity="1.0"/>
  </joint>
  <joint name="tire2" type="revolute">
    <parent link="main"/>
    <child link="tire2"/>
    <axis xyz="0 0 1"/>
    <origin xyz="11.3 -3.0 1.62" rpy="0 0 0"/>
    <limit lower="-1.0" upper="1.0" effort="0" velocity="1.0"/>
  </joint>
  <melchior>
    <camera name="camera_driver" link="main">
      <clip near="0.1" far="100" />
      <origin xyz="14.5 -3.98 7.48" target="16.03 -3.97 7.38" />
    </camera>
    <camera name="camera_birdview" link="main">
      <clip near="0.1" far="100" />
      <origin xyz="6,56 -24.69 11.24" target="6.61 -9.21 7.83" />
    </camera>
  </melchior>
</robot>
