<?xml version="1.0" ?>
<!-- =================================================================================== -->
<!-- |    This document was autogenerated by xacro from ur5_robot.urdf.xacro           | -->
<!-- |    EDITING THIS FILE BY HAND IS NOT RECOMMENDED                                 | -->
<!-- =================================================================================== -->
<robot name="SEP_ship" xmlns:xacro="http://www.ros.org/wiki/xacro">
  <link name="base_link">
    <visual><geometry><mesh filename="meshes/main.glb"/></geometry></visual>
  </link> 

  <link name="leg">
    <visual><geometry><mesh filename="meshes/leg.glb"/></geometry></visual>
  </link>

  <link name="crane_yaw">
    <visual><geometry><mesh filename="meshes/crane_yaw.glb"/></geometry></visual>
  </link>

  <link name="crane_arm1">
    <visual><geometry><mesh filename="meshes/crane_arm1.glb"/></geometry></visual>
  </link>

  <link name="crane_arm2">
    <visual><geometry><mesh filename="meshes/crane_arm2.glb"/></geometry></visual>
  </link>

  <link name="small_crane_yaw">
    <visual><geometry><mesh filename="meshes/small_crane_yaw.glb"/></geometry></visual>
  </link>
  
  <link name="small_crane_arm">
    <visual><geometry><mesh filename="meshes/small_crane_arm.glb"/></geometry></visual>
  </link>
  
  <link name="small_crane_cylinder">
    <visual><geometry><mesh filename="meshes/small_crane_cylinder.glb"/></geometry></visual>
  </link>

  <link name="support1">
    <visual><geometry><mesh filename="meshes/support1.glb"/></geometry></visual>
  </link>
  <link name="support2">
    <visual><geometry><mesh filename="meshes/support2.glb"/></geometry></visual>
  </link>


  <joint name="crane_yaw" type="revolute">
    <parent link="base_link"/>
    <child link="crane_yaw"/>
    <origin xyz="-34.843 -15.30 31.438"/>
    <axis xyz="0 0 1"/>
    <limit lower="-4" upper="4"/>
  </joint>
  <joint name="crane_arm1" type="revolute">
    <parent link="crane_yaw"/>
    <child link="crane_arm1"/>
    <origin xyz="3.851 -1.7588 6.3552"/>
    <axis xyz="0 1 0"/>
    <limit lower="-1.5" upper="0.12"/>
  </joint>
  <joint name="crane_arm2" type="prismatic">
    <parent link="crane_arm1"/>
    <child link="crane_arm2"/>
    <origin xyz="0.0 0.0 0.0"/>
    <axis xyz="1 0 0"/>
    <limit lower="0" upper="61"/>
  </joint>

  <joint name="small_crane_yaw" type="revolute">
    <parent link="base_link"/>
    <child link="small_crane_yaw"/>
    <origin xyz="28.01 23.298 24.106"/>
    <axis xyz="0 0 1"/>
    <limit lower="-2.85" upper="2.5"/>
  </joint>
  <joint name="small_crane_arm" type="revolute">
    <parent link="small_crane_yaw"/>
    <child link="small_crane_arm"/>
    <origin xyz="0.0 0.0 2.9606"/>
    <axis xyz="0 1 0"/>
    <limit lower="-0.5" upper="1.2"/>
  </joint>

  <joint name="leg" type="prismatic">
    <parent link="base_link"/>
    <child link="leg"/>
    <origin xyz="0.0 0.0 0.0"/>
    <axis xyz="0 0 1"/>
    <limit lower="-80" upper="-10"/>
  </joint>

  <joint name="support1" type="fixed">
    <parent link="base_link"/>
    <child link="support1"/>
    <origin xyz="8.9 -26.1 11.85"/>
  </joint>

  <joint name="support2" type="revolute">
    <parent link="support1"/>
    <child link="support2"/>
    <origin xyz="-9.48 -3.85 0.0"/>
    <axis xyz="1 0 0"/>
    <limit lower="-1.75" upper="1.75"/>
  </joint>
</robot>
